<?xml version="1.0" encoding="utf-8"?>
<!-- This URDF was automatically created by SolidWorks to URDF Exporter! Originally created by Stephen Brawner (brawner@gmail.com) 
     Commit Version: 1.6.0-1-g15f4949  Build Version: 1.6.7594.29634
     For more information, please see http://wiki.ros.org/sw_urdf_exporter -->
<robot
  name="Assem1">
  <link
    name="base_link">
    <inertial>
      <origin
        xyz="-1.9652E-17 1.8272E-17 1.6425E-18"
        rpy="0 0 0" />
      <mass
        value="1" />
      <inertia
        ixx="0.11483"
        ixy="8.1635E-18"
        ixz="1.3415E-18"
        iyy="0.26707"
        iyz="3.3662E-18"
        izz="0.27483" />
    </inertial>
    <visual>
      <origin
        xyz="0 0 0"
        rpy="0 0 0" />
      <geometry>
        <mesh
          filename="package://Assem1/meshes/base_link.STL" />
      </geometry>
      <material
        name="white">
        <color
          rgba="1 1 1 1" />
      </material>
    </visual>
    <collision>
      <origin
        xyz="0 0 0"
        rpy="0 0 0" />
      <geometry>
        <mesh
          filename="package://Assem1/meshes/base_link.STL" />
      </geometry>
    </collision>
  </link>
  <link
    name="leg">
    <inertial>
      <origin
        xyz="0 -0.15 0.025"
        rpy="0 0 0" />
      <mass
        value="1" />
      <inertia
        ixx="0.023225"
        ixy="4.5924E-20"
        ixz="-1.2288E-20"
        iyy="0.0018897"
        iyz="-9.035E-20"
        izz="0.024327" />
    </inertial>
    <visual>
      <origin
        xyz="0 0 0"
        rpy="0 0 0" />
      <geometry>
        <mesh
          filename="package://Assem1/meshes/leg.STL" />
      </geometry>
      <material
        name="black">
        <color
          rgba="0 0 0 1" />
      </material>
    </visual>
    <collision>
      <origin
        xyz="0 0 0"
        rpy="0 0 0" />
      <geometry>
        <mesh
          filename="package://Assem1/meshes/leg.STL" />
      </geometry>
    </collision>
  </link>
  <joint
    name="body2leg"
    type="revolute">
    <origin
      xyz="0 -0.15 0"
      rpy="1.5708 0 0" />
    <parent
      link="base_link" />
    <child
      link="leg" />
    <axis
      xyz="0 0 1" />
    <limit
      lower="-4"
      upper="4"
      effort="2"
      velocity="6" />
  </joint>
  <link
    name="feet">
    <inertial>
      <origin
        xyz="-3.576E-19 -0.0013578 0.11566"
        rpy="0 0 0" />
      <mass
        value="1" />
      <inertia
        ixx="0.016617"
        ixy="1.008E-18"
        ixz="-1.253E-18"
        iyy="0.033106"
        iyz="2.3461E-05"
        izz="0.020595" />
    </inertial>
    <visual>
      <origin
        xyz="0 0 0"
        rpy="0 0 0" />
      <geometry>
        <mesh
          filename="package://Assem1/meshes/feet.STL" />
      </geometry>
      <material
        name="white">
        <color
          rgba="1 1 1 1" />
      </material>
    </visual>
    <collision>
      <origin
        xyz="0 0 0"
        rpy="0 0 0" />
      <geometry>
        <mesh
          filename="package://Assem1/meshes/feet.STL" />
      </geometry>
    </collision>
  </link>
  <joint
    name="leg2feet"
    type="revolute">
    <origin
      xyz="0 -0.3 0.05"
      rpy="0 0 0" />
    <parent
      link="leg" />
    <child
      link="feet" />
    <axis
      xyz="0 0 1" />
    <limit
      lower="-4"
      upper="4"
      effort="2"
      velocity="6" />d
  </joint>
</robot>